2021-12-12 11:49:44,487 ERROR: Exception on /home [GET] [in /Users/alex/Developer/timetableSystem/venv/lib/python3.9/site-packages/flask/app.py:1457]
Traceback (most recent call last):
  File "/Users/alex/Developer/timetableSystem/venv/lib/python3.9/site-packages/flask/app.py", line 2073, in wsgi_app
    response = self.full_dispatch_request()
  File "/Users/alex/Developer/timetableSystem/venv/lib/python3.9/site-packages/flask/app.py", line 1518, in full_dispatch_request
    rv = self.handle_user_exception(e)
  File "/Users/alex/Developer/timetableSystem/venv/lib/python3.9/site-packages/flask/app.py", line 1516, in full_dispatch_request
    rv = self.dispatch_request()
  File "/Users/alex/Developer/timetableSystem/venv/lib/python3.9/site-packages/flask/app.py", line 1502, in dispatch_request
    return self.ensure_sync(self.view_functions[rule.endpoint])(**req.view_args)
  File "/Users/alex/Developer/timetableSystem/venv/lib/python3.9/site-packages/flask_login/utils.py", line 272, in decorated_view
    return func(*args, **kwargs)
  File "/Users/alex/Developer/timetableSystem/app/routes.py", line 18, in home
    return render_template('home.html')
  File "/Users/alex/Developer/timetableSystem/venv/lib/python3.9/site-packages/flask/templating.py", line 148, in render_template
    ctx.app.jinja_env.get_or_select_template(template_name_or_list),
  File "/Users/alex/Developer/timetableSystem/venv/lib/python3.9/site-packages/jinja2/environment.py", line 1068, in get_or_select_template
    return self.get_template(template_name_or_list, parent, globals)
  File "/Users/alex/Developer/timetableSystem/venv/lib/python3.9/site-packages/jinja2/environment.py", line 997, in get_template
    return self._load_template(name, globals)
  File "/Users/alex/Developer/timetableSystem/venv/lib/python3.9/site-packages/jinja2/environment.py", line 958, in _load_template
    template = self.loader.load(self, name, self.make_globals(globals))
  File "/Users/alex/Developer/timetableSystem/venv/lib/python3.9/site-packages/jinja2/loaders.py", line 125, in load
    source, filename, uptodate = self.get_source(environment, name)
  File "/Users/alex/Developer/timetableSystem/venv/lib/python3.9/site-packages/flask/templating.py", line 59, in get_source
    return self._get_source_fast(environment, template)
  File "/Users/alex/Developer/timetableSystem/venv/lib/python3.9/site-packages/flask/templating.py", line 95, in _get_source_fast
    raise TemplateNotFound(template)
jinja2.exceptions.TemplateNotFound: home
2021-12-12 11:50:14,555 INFO: Microblog startup [in /Users/alex/Developer/timetableSystem/app/__init__.py:52]
2021-12-12 11:57:37,224 INFO: Microblog startup [in /Users/alex/Developer/timetableSystem/app/__init__.py:52]
2021-12-12 12:00:55,520 INFO: Microblog startup [in /Users/alex/Developer/timetableSystem/app/__init__.py:52]
2021-12-12 12:00:58,874 ERROR: Exception on /manage_users [GET] [in /Users/alex/Developer/timetableSystem/venv/lib/python3.9/site-packages/flask/app.py:1457]
Traceback (most recent call last):
  File "/Users/alex/Developer/timetableSystem/venv/lib/python3.9/site-packages/flask/app.py", line 2073, in wsgi_app
    response = self.full_dispatch_request()
  File "/Users/alex/Developer/timetableSystem/venv/lib/python3.9/site-packages/flask/app.py", line 1518, in full_dispatch_request
    rv = self.handle_user_exception(e)
  File "/Users/alex/Developer/timetableSystem/venv/lib/python3.9/site-packages/flask/app.py", line 1516, in full_dispatch_request
    rv = self.dispatch_request()
  File "/Users/alex/Developer/timetableSystem/venv/lib/python3.9/site-packages/flask/app.py", line 1502, in dispatch_request
    return self.ensure_sync(self.view_functions[rule.endpoint])(**req.view_args)
  File "/Users/alex/Developer/timetableSystem/app/routes.py", line 62, in manage_users
    return render_template('manage_users')
  File "/Users/alex/Developer/timetableSystem/venv/lib/python3.9/site-packages/flask/templating.py", line 148, in render_template
    ctx.app.jinja_env.get_or_select_template(template_name_or_list),
  File "/Users/alex/Developer/timetableSystem/venv/lib/python3.9/site-packages/jinja2/environment.py", line 1068, in get_or_select_template
    return self.get_template(template_name_or_list, parent, globals)
  File "/Users/alex/Developer/timetableSystem/venv/lib/python3.9/site-packages/jinja2/environment.py", line 997, in get_template
    return self._load_template(name, globals)
  File "/Users/alex/Developer/timetableSystem/venv/lib/python3.9/site-packages/jinja2/environment.py", line 958, in _load_template
    template = self.loader.load(self, name, self.make_globals(globals))
  File "/Users/alex/Developer/timetableSystem/venv/lib/python3.9/site-packages/jinja2/loaders.py", line 125, in load
    source, filename, uptodate = self.get_source(environment, name)
  File "/Users/alex/Developer/timetableSystem/venv/lib/python3.9/site-packages/flask/templating.py", line 59, in get_source
    return self._get_source_fast(environment, template)
  File "/Users/alex/Developer/timetableSystem/venv/lib/python3.9/site-packages/flask/templating.py", line 95, in _get_source_fast
    raise TemplateNotFound(template)
jinja2.exceptions.TemplateNotFound: manage_users
2021-12-12 12:01:28,058 INFO: Microblog startup [in /Users/alex/Developer/timetableSystem/app/__init__.py:52]
2021-12-12 12:01:31,091 ERROR: Exception on /manage_users [GET] [in /Users/alex/Developer/timetableSystem/venv/lib/python3.9/site-packages/flask/app.py:1457]
Traceback (most recent call last):
  File "/Users/alex/Developer/timetableSystem/venv/lib/python3.9/site-packages/flask/app.py", line 2073, in wsgi_app
    response = self.full_dispatch_request()
  File "/Users/alex/Developer/timetableSystem/venv/lib/python3.9/site-packages/flask/app.py", line 1518, in full_dispatch_request
    rv = self.handle_user_exception(e)
  File "/Users/alex/Developer/timetableSystem/venv/lib/python3.9/site-packages/flask/app.py", line 1516, in full_dispatch_request
    rv = self.dispatch_request()
  File "/Users/alex/Developer/timetableSystem/venv/lib/python3.9/site-packages/flask/app.py", line 1502, in dispatch_request
    return self.ensure_sync(self.view_functions[rule.endpoint])(**req.view_args)
  File "/Users/alex/Developer/timetableSystem/app/routes.py", line 62, in manage_users
    return render_template('manage_users.html')
  File "/Users/alex/Developer/timetableSystem/venv/lib/python3.9/site-packages/flask/templating.py", line 147, in render_template
    return _render(
  File "/Users/alex/Developer/timetableSystem/venv/lib/python3.9/site-packages/flask/templating.py", line 128, in _render
    rv = template.render(context)
  File "/Users/alex/Developer/timetableSystem/venv/lib/python3.9/site-packages/jinja2/environment.py", line 1291, in render
    self.environment.handle_exception()
  File "/Users/alex/Developer/timetableSystem/venv/lib/python3.9/site-packages/jinja2/environment.py", line 925, in handle_exception
    raise rewrite_traceback_stack(source=source)
  File "/Users/alex/Developer/timetableSystem/app/templates/manage_users.html", line 1, in top-level template code
    {% extends base.html %}
  File "/Users/alex/Developer/timetableSystem/venv/lib/python3.9/site-packages/jinja2/environment.py", line 474, in getattr
    return getattr(obj, attribute)
jinja2.exceptions.UndefinedError: 'base' is undefined
2021-12-12 12:02:06,612 ERROR: Exception on /manage_users [GET] [in /Users/alex/Developer/timetableSystem/venv/lib/python3.9/site-packages/flask/app.py:1457]
Traceback (most recent call last):
  File "/Users/alex/Developer/timetableSystem/venv/lib/python3.9/site-packages/flask/app.py", line 2073, in wsgi_app
    response = self.full_dispatch_request()
  File "/Users/alex/Developer/timetableSystem/venv/lib/python3.9/site-packages/flask/app.py", line 1518, in full_dispatch_request
    rv = self.handle_user_exception(e)
  File "/Users/alex/Developer/timetableSystem/venv/lib/python3.9/site-packages/flask/app.py", line 1516, in full_dispatch_request
    rv = self.dispatch_request()
  File "/Users/alex/Developer/timetableSystem/venv/lib/python3.9/site-packages/flask/app.py", line 1502, in dispatch_request
    return self.ensure_sync(self.view_functions[rule.endpoint])(**req.view_args)
  File "/Users/alex/Developer/timetableSystem/app/routes.py", line 62, in manage_users
    return render_template('manage_users.html')
  File "/Users/alex/Developer/timetableSystem/venv/lib/python3.9/site-packages/flask/templating.py", line 147, in render_template
    return _render(
  File "/Users/alex/Developer/timetableSystem/venv/lib/python3.9/site-packages/flask/templating.py", line 128, in _render
    rv = template.render(context)
  File "/Users/alex/Developer/timetableSystem/venv/lib/python3.9/site-packages/jinja2/environment.py", line 1291, in render
    self.environment.handle_exception()
  File "/Users/alex/Developer/timetableSystem/venv/lib/python3.9/site-packages/jinja2/environment.py", line 925, in handle_exception
    raise rewrite_traceback_stack(source=source)
  File "/Users/alex/Developer/timetableSystem/app/templates/manage_users.html", line 1, in top-level template code
    {% extends 'base.html' %}
  File "/Users/alex/Developer/timetableSystem/venv/lib/python3.9/site-packages/jinja2/environment.py", line 474, in getattr
    return getattr(obj, attribute)
jinja2.exceptions.UndefinedError: 'base' is undefined
2021-12-12 12:02:12,595 INFO: Microblog startup [in /Users/alex/Developer/timetableSystem/app/__init__.py:52]
2021-12-12 12:09:12,849 INFO: Microblog startup [in /Users/alex/Developer/timetableSystem/app/__init__.py:52]
2021-12-12 12:09:30,164 INFO: Microblog startup [in /Users/alex/Developer/timetableSystem/app/__init__.py:52]
2021-12-12 12:12:27,937 INFO: Microblog startup [in /Users/alex/Developer/timetableSystem/app/__init__.py:52]
